<mujoco model="button">
  <compiler angle="radian" coordinate="local"/>
  <option timestep="0.002" gravity="0 0 -9.81"/>
  
  <visual>
    <global offwidth="224" offheight="224"/>
  </visual>
  
  <asset>
    <texture name="grid" type="2d" builtin="checker" width="512" height="512"/>
    <material name="grid" texture="grid" texrepeat="1 1"/>
  </asset>
  
  <worldbody>
    <light pos="0 0 1.5" dir="0 0 -1"/>
    <camera name="fixed" pos="0.8 0.8 0.8" xyaxes="-1 1 0 -0.5 -0.5 1"/>
    <geom name="floor" type="plane" size="2 2 .1" material="grid"/>
    
    <!-- Button panel -->
    <body name="panel" pos="0.5 0 0.4">
      <geom type="box" size="0.15 0.15 0.02" rgba="0.3 0.3 0.3 1"/>
      
      <!-- Button -->
      <body name="button" pos="0 0 0.03">
        <joint name="button_press" type="slide" axis="0 0 1" range="-0.02 0" stiffness="100" damping="10"/>
        <geom type="cylinder" size="0.03 0.01" rgba="1 0 0 1"/>
      </body>
    </body>
    
    <!-- Robot arm -->
    <body name="base" pos="0 0 0.4">
      <geom type="cylinder" size="0.05 0.1" rgba="0.7 0.7 0.7 1"/>
      <joint name="joint0" type="hinge" axis="0 0 1" range="-3.14 3.14" damping="1"/>
      
      <body name="link1" pos="0 0 0.1">
        <geom type="capsule" fromto="0 0 0 0.3 0 0" size="0.03" rgba="0.5 0.5 0.8 1"/>
        <joint name="joint1" type="hinge" axis="0 1 0" range="-1.57 1.57" damping="1"/>
        
        <body name="link2" pos="0.3 0 0">
          <geom type="capsule" fromto="0 0 0 0.3 0 0" size="0.03" rgba="0.5 0.8 0.5 1"/>
          <joint name="joint2" type="hinge" axis="0 1 0" range="-1.57 1.57" damping="1"/>
          
          <body name="ee" pos="0.3 0 0">
            <site name="ee_site" pos="0 0 0" size="0.02"/>
            <geom type="sphere" size="0.04" rgba="0.8 0.2 0.2 1"/>
          </body>
        </body>
      </body>
    </body>
  </worldbody>
  
  <sensor>
    <jointpos name="button_sensor" joint="button_press"/>
  </sensor>
  
  <actuator>
    <position name="act0" joint="joint0" kp="10"/>
    <position name="act1" joint="joint1" kp="10"/>
    <position name="act2" joint="joint2" kp="10"/>
  </actuator>
</mujoco>
